Test Report - 2025-04-04_15-59-25
==================================================

Total Tests Run: 15
Successful: 9
Failed: 6
Errors: 0
Run Time: 0:00:00.243985

Failed Tests:
--------------------
test_file_too_large (test_app.TestImageResizerApp.test_file_too_large)
Traceback (most recent call last):
  File "/Users/ganeshbollem/Documents/image-resizer-app/tests/test_app.py", line 118, in test_file_too_large
    self.assertEqual(response.status_code, 413)
AssertionError: 400 != 413


test_unexpected_error (test_app.TestImageResizerApp.test_unexpected_error)
Traceback (most recent call last):
  File "/Users/ganeshbollem/Documents/image-resizer-app/tests/test_app.py", line 124, in test_unexpected_error
    self.assertEqual(response.status_code, 500)
AssertionError: 404 != 500


test_convert_to_pdf_file_too_large (test_pdf.TestPDFConversion.test_convert_to_pdf_file_too_large)
Traceback (most recent call last):
  File "/Users/ganeshbollem/Documents/image-resizer-app/tests/test_pdf.py", line 76, in test_convert_to_pdf_file_too_large
    self.assertEqual(json_data['error'], 'Individual file size exceeds limit')
AssertionError: 'File size exceeds 10MB limit: large_file.jpg' != 'Individual file size exceeds limit'
- File size exceeds 10MB limit: large_file.jpg
+ Individual file size exceeds limit



test_convert_to_pdf_invalid_file_type (test_pdf.TestPDFConversion.test_convert_to_pdf_invalid_file_type)
Traceback (most recent call last):
  File "/Users/ganeshbollem/Documents/image-resizer-app/tests/test_pdf.py", line 53, in test_convert_to_pdf_invalid_file_type
    self.assertEqual(json_data['error'], 'Invalid file type')
AssertionError: 'Invalid file type: test.txt. Supported formats: PNG, JPG, JPEG, GIF, WebP' != 'Invalid file type'
- Invalid file type: test.txt. Supported formats: PNG, JPG, JPEG, GIF, WebP
+ Invalid file type



test_convert_to_pdf_success (test_pdf.TestPDFConversion.test_convert_to_pdf_success)
Traceback (most recent call last):
  File "/Users/ganeshbollem/Documents/image-resizer-app/tests/test_pdf.py", line 149, in test_convert_to_pdf_success
    self.assertTrue(os.path.exists(pdf_path))
AssertionError: False is not true


test_convert_to_pdf_with_invalid_order (test_pdf.TestPDFConversion.test_convert_to_pdf_with_invalid_order)
Traceback (most recent call last):
  File "/Users/ganeshbollem/Documents/image-resizer-app/tests/test_pdf.py", line 158, in test_convert_to_pdf_with_invalid_order
    self.assertEqual(response.status_code, 400)
AssertionError: 200 != 400


