Test Report - 2025-04-04_10-10-49
==================================================

Total Tests Run: 15
Successful: 4
Failed: 11
Errors: 0
Run Time: 0:00:00.223703

Failed Tests:
--------------------
test_compress_image_invalid_size (test_app.TestImageResizerApp.test_compress_image_invalid_size)
Traceback (most recent call last):
  File "/Users/ganeshbollem/Documents/image-resizer-app/tests/test_app.py", line 76, in test_compress_image_invalid_size
    self.assertEqual(response.status_code, 400)
AssertionError: 500 != 400


test_compress_image_success (test_app.TestImageResizerApp.test_compress_image_success)
Traceback (most recent call last):
  File "/Users/ganeshbollem/Documents/image-resizer-app/tests/test_app.py", line 62, in test_compress_image_success
    self.assertEqual(response.status_code, 200)
AssertionError: 500 != 200


test_file_too_large (test_app.TestImageResizerApp.test_file_too_large)
Traceback (most recent call last):
  File "/Users/ganeshbollem/Documents/image-resizer-app/tests/test_app.py", line 115, in test_file_too_large
    self.assertIn(b'File too large', response.data)
AssertionError: b'File too large' not found in b'{"error":"File size exceeds limit"}\n'


test_resize_image_invalid_dimensions (test_app.TestImageResizerApp.test_resize_image_invalid_dimensions)
Traceback (most recent call last):
  File "/Users/ganeshbollem/Documents/image-resizer-app/tests/test_app.py", line 53, in test_resize_image_invalid_dimensions
    self.assertIn(b'Invalid dimensions', response.data)
AssertionError: b'Invalid dimensions' not found in b'{"error":"Width and height must be positive numbers"}\n'


test_unexpected_error (test_app.TestImageResizerApp.test_unexpected_error)
Traceback (most recent call last):
  File "/Users/ganeshbollem/Documents/image-resizer-app/tests/test_app.py", line 120, in test_unexpected_error
    self.assertIn(b'Internal server error', response.data)
AssertionError: b'Internal server error' not found in b'{"error":"Resource not found"}\n'


test_convert_to_pdf_file_too_large (test_pdf.TestPDFConversion.test_convert_to_pdf_file_too_large)
Traceback (most recent call last):
  File "/Users/ganeshbollem/Documents/image-resizer-app/tests/test_pdf.py", line 60, in test_convert_to_pdf_file_too_large
    self.assertEqual(response.status_code, 413)
AssertionError: 500 != 413


test_convert_to_pdf_invalid_file_type (test_pdf.TestPDFConversion.test_convert_to_pdf_invalid_file_type)
Traceback (most recent call last):
  File "/Users/ganeshbollem/Documents/image-resizer-app/tests/test_pdf.py", line 41, in test_convert_to_pdf_invalid_file_type
    self.assertEqual(response.status_code, 400)
AssertionError: 500 != 400


test_convert_to_pdf_no_files (test_pdf.TestPDFConversion.test_convert_to_pdf_no_files)
Traceback (most recent call last):
  File "/Users/ganeshbollem/Documents/image-resizer-app/tests/test_pdf.py", line 32, in test_convert_to_pdf_no_files
    self.assertEqual(response.status_code, 400)
AssertionError: 500 != 400


test_convert_to_pdf_success (test_pdf.TestPDFConversion.test_convert_to_pdf_success)
Traceback (most recent call last):
  File "/Users/ganeshbollem/Documents/image-resizer-app/tests/test_pdf.py", line 96, in test_convert_to_pdf_success
    self.assertEqual(response.status_code, 200)
AssertionError: 500 != 200


test_convert_to_pdf_total_size_too_large (test_pdf.TestPDFConversion.test_convert_to_pdf_total_size_too_large)
Traceback (most recent call last):
  File "/Users/ganeshbollem/Documents/image-resizer-app/tests/test_pdf.py", line 82, in test_convert_to_pdf_total_size_too_large
    self.assertEqual(response.status_code, 413)
AssertionError: 500 != 413


test_convert_to_pdf_with_invalid_order (test_pdf.TestPDFConversion.test_convert_to_pdf_with_invalid_order)
Traceback (most recent call last):
  File "/Users/ganeshbollem/Documents/image-resizer-app/tests/test_pdf.py", line 116, in test_convert_to_pdf_with_invalid_order
    self.assertEqual(response.status_code, 400)
AssertionError: 500 != 400


