Test Report - 2025-04-04_10-18-31
==================================================

Total Tests Run: 15
Successful: 11
Failed: 4
Errors: 0
Run Time: 0:00:00.209829

Failed Tests:
--------------------
test_unexpected_error (test_app.TestImageResizerApp.test_unexpected_error)
Traceback (most recent call last):
  File "/Users/ganeshbollem/Documents/image-resizer-app/tests/test_app.py", line 126, in test_unexpected_error
    self.assertEqual(json_data['error'], 'The requested URL was not found on the server. If you entered the URL manually please check your spelling and try again.')
AssertionError: 'Resource not found' != 'The requested URL was not found on the se[75 chars]ain.'
- Resource not found
+ The requested URL was not found on the server. If you entered the URL manually please check your spelling and try again.



test_convert_to_pdf_file_too_large (test_pdf.TestPDFConversion.test_convert_to_pdf_file_too_large)
Traceback (most recent call last):
  File "/Users/ganeshbollem/Documents/image-resizer-app/tests/test_pdf.py", line 62, in test_convert_to_pdf_file_too_large
    self.assertEqual(response.status_code, 413)
AssertionError: 400 != 413


test_convert_to_pdf_total_size_too_large (test_pdf.TestPDFConversion.test_convert_to_pdf_total_size_too_large)
Traceback (most recent call last):
  File "/Users/ganeshbollem/Documents/image-resizer-app/tests/test_pdf.py", line 87, in test_convert_to_pdf_total_size_too_large
    self.assertEqual(json_data['error'], 'Total file size exceeds limit')
AssertionError: 'File size exceeds limit' != 'Total file size exceeds limit'
- File size exceeds limit
? ^
+ Total file size exceeds limit
? ^^^^^^^



test_convert_to_pdf_with_invalid_order (test_pdf.TestPDFConversion.test_convert_to_pdf_with_invalid_order)
Traceback (most recent call last):
  File "/Users/ganeshbollem/Documents/image-resizer-app/tests/test_pdf.py", line 120, in test_convert_to_pdf_with_invalid_order
    self.assertEqual(response.status_code, 400)
AssertionError: 500 != 400


